{"nbformat":4,"nbformat_minor":0,"metadata":{"colab":{"provenance":[{"file_id":"1I4oxnP2bLWVkt2WSgOaqV-k5KEYDXvcZ","timestamp":1683155742700}]},"kernelspec":{"name":"python3","display_name":"Python 3"},"language_info":{"name":"python"}},"cells":[{"cell_type":"markdown","source":["## Ada - Data Science - PY - 017 - Aula 6\n","Neste módulo, você será capaz de fazer um Sistema simples de cadastro seguro.\n","\n","Professor da disciplina: Lucio Monteiro."],"metadata":{"id":"9GmRAgULZF3E"}},{"cell_type":"markdown","source":["Dúvidas Aula anterior.\n"],"metadata":{"id":"acEWZ1I4ZFmw"}},{"cell_type":"code","source":[],"metadata":{"id":"b9pOxZGZZGmX"},"execution_count":null,"outputs":[]},{"cell_type":"code","source":[],"metadata":{"id":"cHn9n9IBZGS7"},"execution_count":null,"outputs":[]},{"cell_type":"markdown","source":["# Tratamento de Exceção\n","\n","Você já deve ter notado que algumas operações podem dar errado em certas circunstâncias, e esses erros provocam o tratamento do nosso programa. \n","\n","Por exemplo, quando solicitamos que o usuário digite um número inteiro e ele digita qualquer outra coisa. O erro ocorre especificamente na conversão da entrada para `int`. Veja o exemplo abaixo:\n"],"metadata":{"id":"xIHeuqvzVt91"}},{"cell_type":"code","source":[],"metadata":{"id":"gzn5Y1KB4gYf"},"execution_count":null,"outputs":[]},{"cell_type":"markdown","source":["Note que o erro possui um nome, `ValueError`, e uma mensagem explicando o que ocorreu.\n","\n","Vejamos outro exemplo bastante famoso: a divisão por zero.\n"],"metadata":{"id":"RvhT0zH2V-nL"}},{"cell_type":"code","source":[],"metadata":{"id":"UiDwZxjH4h0t"},"execution_count":null,"outputs":[]},{"cell_type":"markdown","source":["\n","Observe a mesma estrutura do erro anterior: temos um nome (`ZeroDivisionError`) e uma mensagem explicando o que ocorreu.\n","\n","Esses erros, que não são erros de lógica nem de sintaxe, são o que chamamos de **exceções**. São pequenos problemas que o programa pode encontrar durante sua execução, como não encontrar um arquivo ou uma função receber um valor de tipo inesperado.\n","\n","Vamos começar aprendendo como lidar com códigos que podem provocar erros, evitando o travamento do programa, e em seguida iremos aprender a criar as nossas próprias exceções para alertar outros programadores sobre problemas que possam ter ocorrido em nossas classes e funções.\n","\n","> A [documentação oficial](https://docs.python.org/pt-br/3/library/exceptions.html) do Python traz uma lista completa de exceções que já vem prontas e a relação de hierarquia entre elas.\n","\n","## Tratando uma exceção\n","\n","### try/except\n","Tratar uma exceção significa que quando surgir um dos erros mencionados, nós iremos assumir responsabilidade sobre ele e iremos providenciar algum código alternativo. Dessa maneira, o Python não irá mais travar o nosso programa, e sim desviar seu fluxo para o código fornecido.\n","\n","O bloco mais básico para lidarmos com exceção é o `try`/`except`.\n","\n","Dentro do `try` vamos colocar o pedaço de código com potencial para dar erro. Estamos pedindo que o Python **tente** executar aquele código, cientes de que pode não dar certo.\n","\n","Dentro do `except`, colocamos o código que deverá ser executado **somente** se algo de errado ocorrer no `try`. Caso ocorra exceção em alguma linha do `try`, a execução irá **imediatamente** para o `except`, ignorando o restante do código dentro do `try`. Vejamos um exemplo:\n"],"metadata":{"id":"QXnUSkTuXWQm"}},{"cell_type":"code","source":[],"metadata":{"id":"DrxUbYA-4jw_"},"execution_count":null,"outputs":[]},{"cell_type":"markdown","source":["\n","O bloco acima já resolve a grande maioria dos problemas. Mas vamos estudar mais algumas possibilidades para deixar nosso tratamento ainda mais sofisticado e especializado.\n","\n","Você deve ter notado que enfatizamos o fato de exceções poderem ter um nome. Esse nome pode nos ajudar a identificar com sucesso qual dos erros possíveis ocorreu e tratá-lo com sucesso.\n","\n","Vamos considerar a função abaixo:\n"],"metadata":{"id":"8cueBdGdXqE5"}},{"cell_type":"code","source":[],"metadata":{"id":"OMTHLwDt4k3e"},"execution_count":null,"outputs":[]},{"cell_type":"markdown","source":["Um erro óbvio que pode ocorrer nessa função seria o `ZeroDivisionError`, que é obtido quando o zero é passado como segundo parâmetro da função. Porém, ele não é o único erro possível. \n","\n","O que acontece se passarmos um parâmetro que não seja numérico? `TypeError`, pois utilizamos tipos inválidos para o operador de divisão `/`.\n","\n","Podemos colocar diversos `except` após o `try`, cada um testando um tipo diferente de erro. Um último `except` genérico englobará todos os casos que não se encaixarem nos específicos. Veja o exemplo:\n","\n"],"metadata":{"id":"kgsNXnl4X62h"}},{"cell_type":"code","source":[],"metadata":{"id":"9v70j3I54mG1"},"execution_count":null,"outputs":[]},{"cell_type":"markdown","source":["### else\n","\n","Nosso bom e velho `else`, tipicamente usado em expressões condicionais acompanhando um `if`, também pode aparecer em blocos `try`/`except`. Seu efeito é o oposto do `except`: enquanto o `except` é executado quando algo dá errado, o `else` só é executado se absolutamente nada der errado. Por exemplo, poderíamos atualizar nosso exemplo anterior utilizando um `else`:\n","\n"],"metadata":{"id":"ti-4EbMmYGl-"}},{"cell_type":"code","source":[],"metadata":{"id":"pljteM454nPx"},"execution_count":null,"outputs":[]},{"cell_type":"markdown","source":["\n","Note que, no exemplo acima, não tem problema estarmos atribuindo valor pra `div` apenas no bloco `try`. Ela só será usada no `else`, ou seja, só será usada se tudo deu certo.\n","\n","### finally\n","\n","Muitas vezes um erro pode ocorrer quando já realizamos diversas operações. Dentre essas operações, podemos ter solicitado recursos, como por exemplo abrir um arquivo, estabelecer uma conexão com a internet ou alocar uma grande faixa de memória.\n","\n","O que aconteceria, por exemplo, se um comando como `return` aparecesse durante o tratamento deste erro após termos solicitado tantos recursos diferentes? O arquivo ficaria aberto, a conexão ficaria aberta, memória seria desperdiçada, etc.\n","\n","O `finally` garante um local seguro para colocarmos código de limpeza - ou seja, devolver recursos que não serão mais utilizados: fechar arquivos, fechar conexões com servidor etc.\n","\n","Ele **sempre** será executado após um bloco `try`/`except`, mesmo que haja um `return` no caminho.\n","\n","Veja o exemplo abaixo para entender o que queremos dizer:\n","\n"],"metadata":{"id":"8UN8Gkq0Yn6g"}},{"cell_type":"code","source":[],"metadata":{"id":"5l9EIGjm4oci"},"execution_count":null,"outputs":[]},{"cell_type":"markdown","source":["\n","Note que o conteúdo do bloco `finally` foi executado em ambas as chamadas, mesmo havendo um `return` dentro do `try` e outro dentro do `except`. Antes de sair da função e retornar o valor, o Python é obrigado a desviar a execução para o bloco `finally` e executar seu conteúdo.\n","\n","Vejamos um exemplo mais completo: um bloco `try`/`except` tentará criar um arquivo (não se preocupe com detalhes de como arquivos funcionam - estudaremos isso muito em breve!). Dentro do `try`, teremos um bloco `try`/`except`/`finally`. O `try` tentará escrever algumas operações matemáticas no arquivo, o `except` exibirá uma mensagem caso uma operação seja inválida, e o `finally` garantirá que o arquivo será fechado **independentemente de um erro ter ou não ocorrido**.\n","\n"],"metadata":{"id":"NMHL3yA4YyVR"}},{"cell_type":"code","source":[],"metadata":{"id":"KQKRGyZ14pju"},"execution_count":null,"outputs":[]},{"cell_type":"markdown","source":["\n","## Levantando exceções\n","\n","Quando estamos criando nossos próprios módulos, classes ou funções, muitas vezes vamos nos deparar com situações inválidas. Imprimir uma mensagem de erro não é uma boa ideia, pois o programa pode estar rodando em um servidor, pode ter uma interface gráfica, etc.\n","\n","Logo, o ideal seria lançarmos exceções para sinalizar essas situações. Desta forma, se elas forem ignoradas, o programa irá parar, sinalizando para o programador que existe alguma situação que deveria ser tratada. Adicionalmente, podemos criar nossa própria mensagem de erro, sinalizando para o programador que ele deveria fazer algo a respeito.\n","\n","Podemos utilizar a palavra `raise` seguida de `Exception()`, passando entre parênteses a mensagem personalizada de erro. Veja o exemplo:\n"],"metadata":{"id":"1MIctcBPY74S"}},{"cell_type":"code","source":[],"metadata":{"id":"YXVcyGfO4rTy"},"execution_count":null,"outputs":[]},{"cell_type":"markdown","source":["\n","Note que na primeira chamada, onde não ocorreu exceção, o salário foi cadastrado na lista. Já na segunda chamada, nossa função lançou a exceção e parou sua execução.\n","\n","Idealmente, quem pretende utilizar a função deveria fazê-lo agora utilizando `try`, para manter o programa funcionando e tratar adequadamente o problema.\n","\n"],"metadata":{"id":"xg_O9tAOZET-"}},{"cell_type":"code","source":[],"metadata":{"id":"QDYey1dG4svF"},"execution_count":null,"outputs":[]},{"cell_type":"markdown","source":["\n","> O `raise` também pode ser utilizado para lançar exceções que já existem, não necessariamente exceções \"novas\". Basta trocar `Exception()` pelo nome da exceção desejada.\n","> De fato, quando utilizamos `raise Exception()` estamos apenas lançando a exceção mais genérica, da qual outras são derivadas, apenas especificando sua mensagem de erro.\n","\n","## Criando exceções novas\n","\n","> **Nota:** este tópico utiliza conceitos de **programação orientada a objeto**. Ele está aqui para tornar esse capítulo mais completo. Caso você curse um módulo de programação orientada a objeto futuramente, é recomendável reler este material. Em todo caso, é possível utilizar os exemplos deste tópico como modelo para criar exceções mesmo sem compreender os detalhes do que está ocorrendo.\n","\n","### Herdando de Exception\n","Muitos problemas simples podem ser resolvidos através do `raise Exception(mensagem)`. Porém, você deve ter notado nos exemplos anteriores que o nome da nossa mensagem de erro foi `Exception`.\n","\n","Exceções geralmente são implementadas através de classes. O \"nome\" do erro é o nome da classe de cada exceção. Existe uma exceção genérica chamada de `Exception`. Quando usamos `raise Exception(mensagem)`, estamos lançando essa exceção genérica junto de uma mensagem de erro personalizada.\n","\n","O problema da nossa abordagem é que por utilizarmos uma exceção genérica não teremos como adicionar um `except` específico para nossa mensagem. Vamos criar nossa própria classe para escolher o nome do nosso erro. Exceções personalizadas geralmente **herdam** da classe `Exception`. Fazemos isso adicionando `(Exception)` após o nome de nossa classe.\n","\n","Vamos colocar um construtor que recebe uma mensagem. Podemos definir uma mensagem padrão, caso ninguém passe a mensagem. Em seguida, chamaremos o construtor da superclasse `(Exception)`.\n","\n","\n"],"metadata":{"id":"CU2-0KYGZMkp"}},{"cell_type":"code","source":[],"metadata":{"id":"x6r-FusO4ufe"},"execution_count":null,"outputs":[]},{"cell_type":"markdown","source":["Agora sim temos um erro com seu próprio nome e uma mensagem padrão. Mas note que quem está usando a nossa exceção pode personalizar a mensagem se quiser, basta passar uma mensagem diferente entre parênteses. O tipo do erro ainda será o mesmo e ambos deverão ser identificados como `SalarioInvalido` no `Except`.\n"],"metadata":{"id":"dNQJ7UvdZYWy"}},{"cell_type":"code","source":[],"metadata":{"id":"Gx1tK5KY4vrA"},"execution_count":null,"outputs":[]},{"cell_type":"markdown","source":["\n","\n","Para finalizar, vale sempre lembrar que podemos tratar essa exceção específica:\n"],"metadata":{"id":"X6y7UJTSZgMQ"}},{"cell_type":"code","source":[],"metadata":{"id":"VWjxuqT24w3u"},"execution_count":null,"outputs":[]},{"cell_type":"markdown","source":["\n","### Adicionando atributos à exceção\n","\n","É possível uma exceção trazer consigo informações sobre o valor que provocou o erro. Por exemplo, seria útil que a classe `SalarioInvalido` pudesse informar qual foi o salário inválido. Isso é útil, por exemplo, em _logs_ que registram tudo o que ocorreu no programa, além de trazer informações importantes para o _debugging_ do código.\n","\n","Para isso, basta ajustar o construtor da classe de sua exceção:\n","\n"],"metadata":{"id":"j5zoCtCQZn2p"}},{"cell_type":"code","source":[],"metadata":{"id":"MAobmUxW4yIF"},"execution_count":null,"outputs":[]},{"cell_type":"markdown","source":["Agora, ao lançar a exceção, devemos passar o salário:\n","\n"],"metadata":{"id":"rn7MuniIZuvj"}},{"cell_type":"code","source":[],"metadata":{"id":"QPhmG-_g4zTl"},"execution_count":null,"outputs":[]},{"cell_type":"markdown","source":["Por fim, ao tratar a exceção, podemos dar um _alias_ (um \"apelido\") para ela utilizando a palavra `as`. Através desse apelido, podemos acessar seus atributos.\n","\n","Note que imprimir o objeto faz com que sua mensagem seja impressa.\n","\n"],"metadata":{"id":"GDbj6iK2Z2yr"}},{"cell_type":"code","source":[],"metadata":{"id":"KmZiyIC340kV"},"execution_count":null,"outputs":[]},{"cell_type":"markdown","source":["# Exercícios\n","\n","1. O programa abaixo apresenta alguns erros de execução. Sem alterar as estruturas de dados originais (lista e dicionário), faça um tratamento adequado dos erros para exibir as médias corretas de cada aluno ou mensagens de erro significativas para o usuário em português, sem permitir que o programa seja interrompido antes de finalizar sua execução.\n","\n","```python\n","alunos = ['John', 'Paul', 'George', 'Ringo', 'Brian', 'Pete']\n","\n","notas = {\n","    'John':[7.5, 9.0, 8.25, 8.0],\n","    'Paul':[9.0, 8.5, '10.0', 8.5],\n","    'George':[6.0, '7.0', 8.0, 9],\n","    'Ringo':[4.5, 4.0, 6.0, 7.0],\n","    'Pete':[]\n","}\n","\n","for aluno in alunos:\n","    media = sum(notas[aluno])/len(notas[aluno])\n","    print(f'{aluno}:\\t{media}')\n","```"],"metadata":{"id":"jDwLH3HlZ8MN"}},{"cell_type":"code","source":[],"metadata":{"id":"ba6RCACCapz7"},"execution_count":null,"outputs":[]}]}